Workbook

Sheet Raw Data 
A1: Sector | B1: Year | C1: Month | D1: Cereals and products | E1: Meat and fish | F1: Egg | G1: Milk and products | H1: Oils and fats | I1: Fruits | J1: Vegetables | K1: Pulses and products | L1: Sugar and Confectionery | M1: Spices | N1: Non-alcoholic beverages | O1: Prepared meals, snacks, sweets etc. | P1: Food and beverages | Q1: Pan, tobacco and intoxicants | R1: Clothing | S1: Footwear | T1: Clothing and footwear | U1: Housing | V1: Fuel and light | W1: Household goods and services | X1: Health | Y1: Transport and communication | Z1: Recreation and amusement | AA1: Education | AB1: Personal care and effects | AC1: Miscellaneous | AD1: General index
A2: Rural | B2: 2013 | C2: January | D2: 107.5 | E2: 106.3 | F2: 108.1 | G2: 104.9 | H2: 106.1 | I2: 103.9 | J2: 101.9 | K2: 106.1 | L2: 106.8 | M2: 103.1 | N2: 104.8 | O2: 106.7 | P2: 105.5 | Q2: 105.1 | R2: 106.5 | S2: 105.8 | T2: 106.4 | U2: NA | V2: 105.5 | W2: 104.8 | X2: 104 | Y2: 103.3 | Z2: 103.4 | AA2: 103.8 | AB2: 104.7 | AC2: 104 | AD2: 105.1
A3: Urban | B3: 2013 | C3: January | D3: 110.5 | E3: 109.1 | F3: 113 | G3: 103.6 | H3: 103.4 | I3: 102.3 | J3: 102.9 | K3: 105.8 | L3: 105.1 | M3: 101.8 | N3: 105.1 | O3: 107.9 | P3: 105.9 | Q3: 105.2 | R3: 105.9 | S3: 105 | T3: 105.8 | U3: 100.3 | V3: 105.4 | W3: 104.8 | X3: 104.1 | Y3: 103.2 | Z3: 102.9 | AA3: 103.5 | AB3: 104.3 | AC3: 103.7 | AD3: 104
A4: Rural+Urban | B4: 2013 | C4: January | D4: 108.4 | E4: 107.3 | F4: 110 | G4: 104.4 | H4: 105.1 | I4: 103.2 | J4: 102.2 | K4: 106 | L4: 106.2 | M4: 102.7 | N4: 104.9 | O4: 107.3 | P4: 105.6 | Q4: 105.1 | R4: 106.3 | S4: 105.5 | T4: 106.2 | U4: 100.3 | V4: 105.5 | W4: 104.8 | X4: 104 | Y4: 103.2 | Z4: 103.1 | AA4: 103.6 | AB4: 104.5 | AC4: 103.9 | AD4: 104.6
A5: Rural | B5: 2013 | C5: February | D5: 109.2 | E5: 108.7 | F5: 110.2 | G5: 105.4 | H5: 106.7 | I5: 104 | J5: 102.4 | K5: 105.9 | L5: 105.7 | M5: 103.1 | N5: 105.1 | O5: 107.7 | P5: 106.3 | Q5: 105.6 | R5: 107.1 | S5: 106.3 | T5: 107 | U5: NA | V5: 106.2 | W5: 105.2 | X5: 104.4 | Y5: 103.9 | Z5: 104 | AA5: 104.1 | AB5: 104.6 | AC5: 104.4 | AD5: 105.8
A6: Urban | B6: 2013 | C6: February | D6: 112.9 | E6: 112.9 | F6: 116.9 | G6: 104 | H6: 103.5 | I6: 103.1 | J6: 104.9 | K6: 104.1 | L6: 103.8 | M6: 102.3 | N6: 106 | O6: 109 | P6: 107.2 | Q6: 106 | R6: 106.6 | S6: 105.5 | T6: 106.4 | U6: 100.4 | V6: 105.7 | W6: 105.2 | X6: 104.7 | Y6: 104.4 | Z6: 103.3 | AA6: 103.7 | AB6: 104.3 | AC6: 104.3 | AD6: 104.7
A7: Rural+Urban | B7: 2013 | C7: February | D7: 110.4 | E7: 110.2 | F7: 112.8 | G7: 104.9 | H7: 105.5 | I7: 103.6 | J7: 103.2 | K7: 105.3 | L7: 105.1 | M7: 102.8 | N7: 105.5 | O7: 108.3 | P7: 106.6 | Q7: 105.7 | R7: 106.9 | S7: 106 | T7: 106.8 | U7: 100.4 | V7: 106 | W7: 105.2 | X7: 104.5 | Y7: 104.2 | Z7: 103.6 | AA7: 103.9 | AB7: 104.5 | AC7: 104.4 | AD7: 105.3
A8: Rural | B8: 2013 | C8: March | D8: 110.2 | E8: 108.8 | F8: 109.9 | G8: 105.6 | H8: 106.2 | I8: 105.7 | J8: 101.4 | K8: 105.7 | L8: 105 | M8: 103.3 | N8: 105.6 | O8: 108.2 | P8: 106.6 | Q8: 106.5 | R8: 107.6 | S8: 106.8 | T8: 107.5 | U8: NA | V8: 106.1 | W8: 105.6 | X8: 104.7 | Y8: 104.6 | Z8: 104 | AA8: 104.3 | AB8: 104.3 | AC8: 104.6 | AD8: 106
A9: Urban | B9: 2013 | C9: March | D9: 113.9 | E9: 111.4 | F9: 113.2 | G9: 104.3 | H9: 102.7 | I9: 104.9 | J9: 103.8 | K9: 103.5 | L9: 102.6 | M9: 102.4 | N9: 107 | O9: 109.8 | P9: 107.3 | Q9: 106.8 | R9: 107.2 | S9: 106 | T9: 107 | U9: 100.4 | V9: 106 | W9: 105.7 | X9: 105.2 | Y9: 105.5 | Z9: 103.5 | AA9: 103.8 | AB9: 104.2 | AC9: 104.9 | AD9: 105
A10: Rural+Urban | B10: 2013 | C10: March | D10: 111.4 | E10: 109.7 | F10: 111.2 | G10: 105.1 | H10: 104.9 | I10: 105.3 | J10: 102.2 | K10: 105 | L10: 104.2 | M10: 103 | N10: 106.2 | O10: 108.9 | P10: 106.9 | Q10: 106.6 | R10: 107.4 | S10: 106.5 | T10: 107.3 | U10: 100.4 | V10: 106.1 | W10: 105.6 | X10: 104.9 | Y10: 105.1 | Z10: 103.7 | AA10: 104 | AB10: 104.3 | AC10: 104.7 | AD10: 105.5
A11: Rural | B11: 2013 | C11: April | D11: 110.2 | E11: 109.5 | F11: 106.9 | G11: 106.3 | H11: 105.7 | I11: 108.3 | J11: 103.4 | K11: 105.7 | L11: 104.2 | M11: 103.2 | N11: 106.5 | O11: 108.8 | P11: 107.1 | Q11: 107.1 | R11: 108.1 | S11: 107.4 | T11: 108 | U11: NA | V11: 106.5 | W11: 106.1 | X11: 105.1 | Y11: 104.4 | Z11: 104.5 | AA11: 104.8 | AB11: 102.7 | AC11: 104.6 | AD11: 106.4
A12: Urban | B12: 2013 | C12: April | D12: 114.6 | E12: 113.4 | F12: 106 | G12: 104.7 | H12: 102.1 | I12: 109.5 | J12: 109.7 | K12: 104.6 | L12: 102 | M12: 103.5 | N12: 108.2 | O12: 110.6 | P12: 108.8 | Q12: 108.5 | R12: 107.9 | S12: 106.4 | T12: 107.7 | U12: 100.5 | V12: 106.4 | W12: 106.5 | X12: 105.7 | Y12: 105 | Z12: 104 | AA12: 105.2 | AB12: 103.2 | AC12: 105.1 | AD12: 105.7
A13: Rural+Urban | B13: 2013 | C13: April | D13: 111.6 | E13: 110.9 | F13: 106.6 | G13: 105.7 | H13: 104.4 | I13: 108.9 | J13: 105.5 | K13: 105.3 | L13: 103.5 | M13: 103.3 | N13: 107.2 | O13: 109.6 | P13: 107.7 | Q13: 107.5 | R13: 108 | S13: 107 | T13: 107.9 | U13: 100.5 | V13: 106.5 | W13: 106.3 | X13: 105.3 | Y13: 104.7 | Z13: 104.2 | AA13: 105 | AB13: 102.9 | AC13: 104.8 | AD13: 106.1
A14: Rural | B14: 2013 | C14: May | D14: 110.9 | E14: 109.8 | F14: 105.9 | G14: 107.5 | H14: 105.3 | I14: 108.1 | J14: 107.3 | K14: 106.1 | L14: 103.7 | M14: 104 | N14: 107.4 | O14: 109.9 | P14: 108.1 | Q14: 108.1 | R14: 108.8 | S14: 107.9 | T14: 108.6 | U14: NA | V14: 107.5 | W14: 106.8 | X14: 105.7 | Y14: 104.1 | Z14: 105 | AA14: 105.5 | AB14: 102.1 | AC14: 104.8 | AD14: 107.2
A15: Urban | B15: 2013 | C15: May | D15: 115.4 | E15: 114.2 | F15: 102.7 | G15: 105.5 | H15: 101.5 | I15: 110.6 | J15: 123.7 | K15: 105.2 | L15: 101.9 | M15: 105 | N15: 109.1 | O15: 111.3 | P15: 111.1 | Q15: 109.8 | R15: 108.5 | S15: 106.7 | T15: 108.3 | U15: 100.5 | V15: 107.2 | W15: 107.1 | X15: 106.2 | Y15: 103.9 | Z15: 104.6 | AA15: 105.7 | AB15: 102.6 | AC15: 104.9 | AD15: 106.6
A16: Rural+Urban | B16: 2013 | C16: May | D16: 112.3 | E16: 111.3 | F16: 104.7 | G16: 106.8 | H16: 103.9 | I16: 109.3 | J16: 112.9 | K16: 105.8 | L16: 103.1 | M16: 104.3 | N16: 108.1 | O16: 110.5 | P16: 109.2 | Q16: 108.6 | R16: 108.7 | S16: 107.4 | T16: 108.5 | U16: 100.5 | V16: 107.4 | W16: 106.9 | X16: 105.9 | Y16: 104 | Z16: 104.8 | AA16: 105.6 | AB16: 102.3 | AC16: 104.8 | AD16: 106.9
A17: Rural | B17: 2013 | C17: June | D17: 112.3 | E17: 112.1 | F17: 108.1 | G17: 108.3 | H17: 105.9 | I17: 109.2 | J17: 118 | K17: 106.8 | L17: 104.1 | M17: 105.4 | N17: 108.2 | O17: 111 | P17: 110.6 | Q17: 109 | R17: 109.7 | S17: 108.8 | T17: 109.5 | U17: NA | V17: 108.5 | W17: 107.5 | X17: 106.3 | Y17: 105 | Z17: 105.6 | AA17: 106.5 | AB17: 102.5 | AC17: 105.5 | AD17: 108.9
A18: Urban | B18: 2013 | C18: June | D18: 117 | E18: 120.1 | F18: 112.5 | G18: 107.3 | H18: 101.3 | I18: 112.4 | J18: 143.6 | K18: 105.4 | L18: 101.4 | M18: 106.4 | N18: 110 | O18: 112.2 | P18: 115 | Q18: 110.9 | R18: 109.2 | S18: 107.2 | T18: 108.9 | U18: 106.6 | V18: 108 | W18: 107.7 | X18: 106.5 | Y18: 105.2 | Z18: 105.2 | AA18: 108.1 | AB18: 103.3 | AC18: 106.1 | AD18: 109.7
A19: Rural+Urban | B19: 2013 | C19: June | D19: 113.8 | E19: 114.9 | F19: 109.8 | G19: 107.9 | H19: 104.2 | I19: 110.7 | J19: 126.7 | K19: 106.3 | L19: 103.2 | M19: 105.7 | N19: 109 | O19: 111.6 | P19: 112.2 | Q19: 109.5 | R19: 109.5 | S19: 108.1 | T19: 109.3 | U19: 106.6 | V19: 108.3 | W19: 107.6 | X19: 106.4 | Y19: 105.1 | Z19: 105.4 | AA19: 107.4 | AB19: 102.8 | AC19: 105.8 | AD19: 109.3
A20: Rural | B20: 2013 | C20: July | D20: 113.4 | E20: 114.9 | F20: 110.5 | G20: 109.3 | H20: 106.2 | I20: 110.3 | J20: 129.2 | K20: 107.1 | L20: 104.3 | M20: 106.4 | N20: 109.1 | O20: 112.1 | P20: 113.1 | Q20: 109.8 | R20: 110.5 | S20: 109.5 | T20: 110.3 | U20: NA | V20: 109.5 | W20: 108.3 | X20: 106.9 | Y20: 106.8 | Z20: 106.4 | AA20: 107.8 | AB20: 102.5 | AC20: 106.5 | AD20: 110.7
A21: Urban | B21: 2013 | C21: July | D21: 117.8 | E21: 119.2 | F21: 114 | G21: 108.3 | H21: 101.1 | I21: 113.2 | J21: 160.9 | K21: 105.1 | L21: 101.3 | M21: 107.5 | N21: 110.4 | O21: 113.1 | P21: 117.5 | Q21: 111.7 | R21: 109.8 | S21: 107.8 | T21: 109.5 | U21: 107.7 | V21: 108.6 | W21: 108.1 | X21: 107.1 | Y21: 107.3 | Z21: 105.9 | AA21: 110.1 | AB21: 103.2 | AC21: 107.3 | AD21: 111.4
A22: Rural+Urban | B22: 2013 | C22: July | D22: 114.8 | E22: 116.4 | F22: 111.9 | G22: 108.9 | H22: 104.3 | I22: 111.7 | J22: 140 | K22: 106.4 | L22: 103.3 | M22: 106.8 | N22: 109.6 | O22: 112.6 | P22: 114.7 | Q22: 110.3 | R22: 110.2 | S22: 108.8 | T22: 110 | U22: 107.7 | V22: 109.2 | W22: 108.2 | X22: 107 | Y22: 107.1 | Z22: 106.1 | AA22: 109.1 | AB22: 102.8 | AC22: 106.9 | AD22: 111
A23: Rural | B23: 2013 | C23: August | D23: 114.3 | E23: 115.4 | F23: 111.1 | G23: 110 | H23: 106.4 | I23: 110.8 | J23: 138.9 | K23: 107.4 | L23: 104.1 | M23: 106.9 | N23: 109.7 | O23: 112.6 | P23: 114.9 | Q23: 110.7 | R23: 111.3 | S23: 110.2 | T23: 111.1 | U23: NA | V23: 109.9 | W23: 108.7 | X23: 107.5 | Y23: 107.8 | Z23: 106.8 | AA23: 108.7 | AB23: 105 | AC23: 107.5 | AD23: 112.1
A24: Urban | B24: 2013 | C24: August | D24: 118.3 | E24: 120.4 | F24: 112.7 | G24: 108.9 | H24: 101.1 | I24: 108.7 | J24: 177 | K24: 104.7 | L24: 101 | M24: 108.5 | N24: 110.9 | O24: 114.3 | P24: 119.6 | Q24: 112.4 | R24: 110.6 | S24: 108.3 | T24: 110.2 | U24: 108.9 | V24: 109.3 | W24: 108.7 | X24: 107.6 | Y24: 108.1 | Z24: 106.5 | AA24: 110.8 | AB24: 106 | AC24: 108.3 | AD24: 112.7
A25: Rural+Urban | B25: 2013 | C25: August | D25: 115.6 | E25: 117.2 | F25: 111.7 | G25: 109.6 | H25: 104.5 | I25: 109.8 | J25: 151.8 | K25: 106.5 | L25: 103.1 | M25: 107.4 | N25: 110.2 | O25: 113.4 | P25: 116.6 | Q25: 111.2 | R25: 111 | S25: 109.4 | T25: 110.7 | U25: 108.9 | V25: 109.7 | W25: 108.7 | X25: 107.5 | Y25: 108 | Z25: 106.6 | AA25: 109.9 | AB25: 105.4 | AC25: 107.9 | AD25: 112.4
A26: Rural | B26: 2013 | C26: September | D26: 115.4 | E26: 115.7 | F26: 111.7 | G26: 111 | H26: 107.4 | I26: 110.9 | J26: 154 | K26: 108.1 | L26: 104.2 | M26: 107.9 | N26: 110.4 | O26: 114 | P26: 117.8 | Q26: 111.7 | R26: 112.7 | S26: 111.4 | T26: 112.5 | U26: NA | V26: 111.1 | W26: 109.6 | X26: 108.3 | Y26: 109.3 | Z26: 107.7 | AA26: 109.8 | AB26: 106.7 | AC26: 108.7 | AD26: 114.2
A27: Urban | B27: 2013 | C27: September | D27: 118.6 | E27: 119.1 | F27: 113.2 | G27: 109.6 | H27: 101.7 | I27: 103.2 | J27: 174.3 | K27: 105.1 | L27: 100.8 | M27: 109.1 | N27: 111.1 | O27: 115.4 | P27: 119.2 | Q27: 112.9 | R27: 111.4 | S27: 109 | T27: 111.1 | U27: 109.7 | V27: 109.5 | W27: 109.6 | X27: 107.9 | Y27: 110.4 | Z27: 107.4 | AA27: 111.2 | AB27: 106.9 | AC27: 109.4 | AD27: 113.2
A28: Rural+Urban | B28: 2013 | C28: September | D28: 116.4 | E28: 116.9 | F28: 112.3 | G28: 110.5 | H28: 105.3 | I28: 107.3 | J28: 160.9 | K28: 107.1 | L28: 103.1 | M28: 108.3 | N28: 110.7 | O28: 114.6 | P28: 118.3 | Q28: 112 | R28: 112.2 | S28: 110.4 | T28: 111.9 | U28: 109.7 | V28: 110.5 | W28: 109.6 | X28: 108.1 | Y28: 109.9 | Z28: 107.5 | AA28: 110.6 | AB28: 106.8 | AC28: 109 | AD28: 113.7
A29: Rural | B29: 2013 | C29: October | D29: 116.3 | E29: 115.4 | F29: 112.6 | G29: 111.7 | H29: 107.7 | I29: 113.2 | J29: 164.9 | K29: 108.3 | L29: 103.9 | M29: 108.2 | N29: 111.1 | O29: 114.9 | P29: 119.8 | Q29: 112.2 | R29: 113.6 | S29: 112.3 | T29: 113.4 | U29: NA | V29: 111.6 | W29: 110.4 | X29: 108.9 | Y29: 109.3 | Z29: 108.3 | AA29: 110.2 | AB29: 107.5 | AC29: 109.1 | AD29: 115.5
A30: Urban | B30: 2013 | C30: October | D30: 118.9 | E30: 118.1 | F30: 114.5 | G30: 110.4 | H30: 102.3 | I30: 106.2 | J30: 183.5 | K30: 105.3 | L30: 100.2 | M30: 109.6 | N30: 111.4 | O30: 116 | P30: 120.8 | Q30: 113.5 | R30: 112.5 | S30: 109.7 | T30: 112 | U30: 110.5 | V30: 109.7 | W30: 110.2 | X30: 108.2 | Y30: 109.7 | Z30: 108 | AA30: 111.3 | AB30: 107.3 | AC30: 109.4 | AD30: 114
A31: Rural+Urban | B31: 2013 | C31: October | D31: 117.1 | E31: 116.3 | F31: 113.3 | G31: 111.2 | H31: 105.7 | I31: 109.9 | J31: 171.2 | K31: 107.3 | L31: 102.7 | M31: 108.7 | N31: 111.2 | O31: 115.4 | P31: 120.2 | Q31: 112.5 | R31: 113.2 | S31: 111.2 | T31: 112.8 | U31: 110.5 | V31: 110.9 | W31: 110.3 | X31: 108.6 | Y31: 109.5 | Z31: 108.1 | AA31: 110.8 | AB31: 107.4 | AC31: 109.2 | AD31: 114.8
A32: Rural | B32: 2013 | C32: November | D32: 117.3 | E32: 114.9 | F32: 116.2 | G32: 112.8 | H32: 108.9 | I32: 116.6 | J32: 178.1 | K32: 109.1 | L32: 103.6 | M32: 109 | N32: 111.8 | O32: 116 | P32: 122.5 | Q32: 112.8 | R32: 114.6 | S32: 113.1 | T32: 114.4 | U32: NA | V32: 112.6 | W32: 111.3 | X32: 109.7 | Y32: 109.6 | Z32: 108.7 | AA32: 111 | AB32: 108.2 | AC32: 109.8 | AD32: 117.4
A33: Urban | B33: 2013 | C33: November | D33: 119.8 | E33: 116.3 | F33: 122.6 | G33: 112 | H33: 103.2 | I33: 110 | J33: 192.8 | K33: 106.3 | L33: 99.5 | M33: 110.3 | N33: 111.8 | O33: 117.1 | P33: 122.9 | Q33: 114.1 | R33: 113.5 | S33: 110.3 | T33: 113 | U33: 111.1 | V33: 110 | W33: 110.9 | X33: 108.6 | Y33: 109.5 | Z33: 108.5 | AA33: 111.3 | AB33: 107.9 | AC33: 109.6 | AD33: 115
A34: Rural+Urban | B34: 2013 | C34: November | D34: 118.1 | E34: 115.4 | F34: 118.7 | G34: 112.5 | H34: 106.8 | I34: 113.5 | J34: 183.1 | K34: 108.2 | L34: 102.2 | M34: 109.4 | N34: 111.8 | O34: 116.5 | P34: 122.6 | Q34: 113.1 | R34: 114.2 | S34: 111.9 | T34: 113.8 | U34: 111.1 | V34: 111.6 | W34: 111.1 | X34: 109.3 | Y34: 109.5 | Z34: 108.6 | AA34: 111.2 | AB34: 108.1 | AC34: 109.7 | AD34: 116.3
A35: Rural | B35: 2013 | C35: December | D35: 118.4 | E35: 115.9 | F35: 120.4 | G35: 113.8 | H35: 109.5 | I35: 115.5 | J35: 145.7 | K35: 109.5 | L35: 102.9 | M35: 109.8 | N35: 112.1 | O35: 116.8 | P35: 118.7 | Q35: 113.6 | R35: 115.8 | S35: 114 | T35: 115.5 | U35: NA | V35: 112.8 | W35: 112.1 | X35: 110.1 | Y35: 109.9 | Z35: 109.2 | AA35: 111.6 | AB35: 108.1 | AC35: 110.1 | AD35: 115.5
A36: Urban | B36: 2013 | C36: December | D36: 120.5 | E36: 118.1 | F36: 128.5 | G36: 112.8 | H36: 103.4 | I36: 110.7 | J36: 144.8 | K36: 107.1 | L36: 98.6 | M36: 111.9 | N36: 112.1 | O36: 118.1 | P36: 117.8 | Q36: 115 | R36: 114.2 | S36: 110.9 | T36: 113.7 | U36: 110.7 | V36: 110.4 | W36: 111.3 | X36: 109 | Y36: 109.7 | Z36: 108.9 | AA36: 111.4 | AB36: 107.7 | AC36: 109.8 | AD36: 113.3
A37: Rural+Urban | B37: 2013 | C37: December | D37: 119.1 | E37: 116.7 | F37: 123.5 | G37: 113.4 | H37: 107.3 | I37: 113.3 | J37: 145.4 | K37: 108.7 | L37: 101.5 | M37: 110.5 | N37: 112.1 | O37: 117.4 | P37: 118.4 | Q37: 114 | R37: 115.2 | S37: 112.7 | T37: 114.8 | U37: 110.7 | V37: 111.9 | W37: 111.7 | X37: 109.7 | Y37: 109.8 | Z37: 109 | AA37: 111.5 | AB37: 107.9 | AC37: 110 | AD37: 114.5
A38: Rural | B38: 2014 | C38: January | D38: 118.9 | E38: 117.1 | F38: 120.5 | G38: 114.4 | H38: 109 | I38: 115.5 | J38: 123.9 | K38: 109.6 | L38: 101.8 | M38: 110.2 | N38: 112.4 | O38: 117.3 | P38: 116 | Q38: 114 | R38: 116.5 | S38: 114.5 | T38: 116.2 | U38: NA | V38: 113 | W38: 112.6 | X38: 110.6 | Y38: 110.5 | Z38: 109.6 | AA38: 111.8 | AB38: 108.3 | AC38: 110.6 | AD38: 114.2
A39: Urban | B39: 2014 | C39: January | D39: 121.2 | E39: 122 | F39: 129.9 | G39: 113.6 | H39: 102.9 | I39: 112.1 | J39: 118.9 | K39: 107.5 | L39: 96.9 | M39: 112.7 | N39: 112.1 | O39: 119 | P39: 115.5 | Q39: 115.7 | R39: 114.8 | S39: 111.3 | T39: 114.3 | U39: 111.6 | V39: 111 | W39: 111.9 | X39: 109.7 | Y39: 110.8 | Z39: 109.8 | AA39: 111.5 | AB39: 108 | AC39: 110.5 | AD39: 112.9
A40: Rural+Urban | B40: 2014 | C40: January | D40: 119.6 | E40: 118.8 | F40: 124.1 | G40: 114.1 | H40: 106.8 | I40: 113.9 | J40: 122.2 | K40: 108.9 | L40: 100.2 | M40: 111 | N40: 112.3 | O40: 118.1 | P40: 115.8 | Q40: 114.5 | R40: 115.8 | S40: 113.2 | T40: 115.4 | U40: 111.6 | V40: 112.2 | W40: 112.3 | X40: 110.3 | Y40: 110.7 | Z40: 109.7 | AA40: 111.6 | AB40: 108.2 | AC40: 110.6 | AD40: 113.6
...

Sheet Data Cleaning
A1: Data Cleaning
A3: 1. Checked Data Type
A4: 2. Checked For Blankspaces using CountBlank Function
A5: 3. Created a New Sheet which only have Rural+Urban Sector do carry out further analysis smoothly
A6: 4. Created a Date Column
A7: 5. Created Covid Period Column by the help of IF Function
A8: 6. Created a New Sheet for Broder Category Mapping & CPI Infaltion Index per Broder Category
A9: 7. Replaced the NA with the Mean

Sheet Data for R+U
A1: Sector | B1: Year | C1: Month | D1: Date | E1: Covid Period | F1: Cereals and products | G1: Meat and fish | H1: Egg | I1: Milk and products | J1: Oils and fats | K1: Fruits | L1: Vegetables | M1: Pulses and products | N1: Sugar and Confectionery | O1: Spices | P1: Non-alcoholic beverages | Q1: Prepared meals, snacks, sweets etc. | R1: Food and beverages | S1: Pan, tobacco and intoxicants | T1: Clothing | U1: Footwear | V1: Clothing and footwear | W1: Housing | X1: Fuel and light | Y1: Household goods and services | Z1: Health | AA1: Transport and communication | AB1: Recreation and amusement | AC1: Education | AD1: Personal care and effects | AE1: Miscellaneous | AF1: General index
A2: Rural+Urban | B2: 2013 | C2: January | D2: 41275 | E2: =IF(D2<DATE(2020,3,1),"Pre-Covid","Post-Covid") -> Pre-Covid | F2: 108.4 | G2: 107.3 | H2: 110 | I2: 104.4 | J2: 105.1 | K2: 103.2 | L2: 102.2 | M2: 106 | N2: 106.2 | O2: 102.7 | P2: 104.9 | Q2: 107.3 | R2: 105.6 | S2: 105.1 | T2: 106.3 | U2: 105.5 | V2: 106.2 | W2: 100.3 | X2: 105.5 | Y2: 104.8 | Z2: 104 | AA2: 103.2 | AB2: 103.1 | AC2: 103.6 | AD2: 104.5 | AE2: 103.9 | AF2: 104.6
A3: Rural+Urban | B3: 2013 | C3: February | D3: 41306 | E3: =IF(D3<DATE(2020,3,1),"Pre-Covid","Post-Covid") -> Pre-Covid | F3: 110.4 | G3: 110.2 | H3: 112.8 | I3: 104.9 | J3: 105.5 | K3: 103.6 | L3: 103.2 | M3: 105.3 | N3: 105.1 | O3: 102.8 | P3: 105.5 | Q3: 108.3 | R3: 106.6 | S3: 105.7 | T3: 106.9 | U3: 106 | V3: 106.8 | W3: 100.4 | X3: 106 | Y3: 105.2 | Z3: 104.5 | AA3: 104.2 | AB3: 103.6 | AC3: 103.9 | AD3: 104.5 | AE3: 104.4 | AF3: 105.3
A4: Rural+Urban | B4: 2013 | C4: March | D4: 41334 | E4: =IF(D4<DATE(2020,3,1),"Pre-Covid","Post-Covid") -> Pre-Covid | F4: 111.4 | G4: 109.7 | H4: 111.2 | I4: 105.1 | J4: 104.9 | K4: 105.3 | L4: 102.2 | M4: 105 | N4: 104.2 | O4: 103 | P4: 106.2 | Q4: 108.9 | R4: 106.9 | S4: 106.6 | T4: 107.4 | U4: 106.5 | V4: 107.3 | W4: 100.4 | X4: 106.1 | Y4: 105.6 | Z4: 104.9 | AA4: 105.1 | AB4: 103.7 | AC4: 104 | AD4: 104.3 | AE4: 104.7 | AF4: 105.5
A5: Rural+Urban | B5: 2013 | C5: April | D5: 41365 | E5: =IF(D5<DATE(2020,3,1),"Pre-Covid","Post-Covid") -> Pre-Covid | F5: 111.6 | G5: 110.9 | H5: 106.6 | I5: 105.7 | J5: 104.4 | K5: 108.9 | L5: 105.5 | M5: 105.3 | N5: 103.5 | O5: 103.3 | P5: 107.2 | Q5: 109.6 | R5: 107.7 | S5: 107.5 | T5: 108 | U5: 107 | V5: 107.9 | W5: 100.5 | X5: 106.5 | Y5: 106.3 | Z5: 105.3 | AA5: 104.7 | AB5: 104.2 | AC5: 105 | AD5: 102.9 | AE5: 104.8 | AF5: 106.1
A6: Rural+Urban | B6: 2013 | C6: May | D6: 41395 | E6: =IF(D6<DATE(2020,3,1),"Pre-Covid","Post-Covid") -> Pre-Covid | F6: 112.3 | G6: 111.3 | H6: 104.7 | I6: 106.8 | J6: 103.9 | K6: 109.3 | L6: 112.9 | M6: 105.8 | N6: 103.1 | O6: 104.3 | P6: 108.1 | Q6: 110.5 | R6: 109.2 | S6: 108.6 | T6: 108.7 | U6: 107.4 | V6: 108.5 | W6: 100.5 | X6: 107.4 | Y6: 106.9 | Z6: 105.9 | AA6: 104 | AB6: 104.8 | AC6: 105.6 | AD6: 102.3 | AE6: 104.8 | AF6: 106.9
A7: Rural+Urban | B7: 2013 | C7: June | D7: 41426 | E7: =IF(D7<DATE(2020,3,1),"Pre-Covid","Post-Covid") -> Pre-Covid | F7: 113.8 | G7: 114.9 | H7: 109.8 | I7: 107.9 | J7: 104.2 | K7: 110.7 | L7: 126.7 | M7: 106.3 | N7: 103.2 | O7: 105.7 | P7: 109 | Q7: 111.6 | R7: 112.2 | S7: 109.5 | T7: 109.5 | U7: 108.1 | V7: 109.3 | W7: 106.6 | X7: 108.3 | Y7: 107.6 | Z7: 106.4 | AA7: 105.1 | AB7: 105.4 | AC7: 107.4 | AD7: 102.8 | AE7: 105.8 | AF7: 109.3
A8: Rural+Urban | B8: 2013 | C8: July | D8: 41456 | E8: =IF(D8<DATE(2020,3,1),"Pre-Covid","Post-Covid") -> Pre-Covid | F8: 114.8 | G8: 116.4 | H8: 111.9 | I8: 108.9 | J8: 104.3 | K8: 111.7 | L8: 140 | M8: 106.4 | N8: 103.3 | O8: 106.8 | P8: 109.6 | Q8: 112.6 | R8: 114.7 | S8: 110.3 | T8: 110.2 | U8: 108.8 | V8: 110 | W8: 107.7 | X8: 109.2 | Y8: 108.2 | Z8: 107 | AA8: 107.1 | AB8: 106.1 | AC8: 109.1 | AD8: 102.8 | AE8: 106.9 | AF8: 111
A9: Rural+Urban | B9: 2013 | C9: August | D9: 41487 | E9: =IF(D9<DATE(2020,3,1),"Pre-Covid","Post-Covid") -> Pre-Covid | F9: 115.6 | G9: 117.2 | H9: 111.7 | I9: 109.6 | J9: 104.5 | K9: 109.8 | L9: 151.8 | M9: 106.5 | N9: 103.1 | O9: 107.4 | P9: 110.2 | Q9: 113.4 | R9: 116.6 | S9: 111.2 | T9: 111 | U9: 109.4 | V9: 110.7 | W9: 108.9 | X9: 109.7 | Y9: 108.7 | Z9: 107.5 | AA9: 108 | AB9: 106.6 | AC9: 109.9 | AD9: 105.4 | AE9: 107.9 | AF9: 112.4
A10: Rural+Urban | B10: 2013 | C10: September | D10: 41518 | E10: =IF(D10<DATE(2020,3,1),"Pre-Covid","Post-Covid") -> Pre-Covid | F10: 116.4 | G10: 116.9 | H10: 112.3 | I10: 110.5 | J10: 105.3 | K10: 107.3 | L10: 160.9 | M10: 107.1 | N10: 103.1 | O10: 108.3 | P10: 110.7 | Q10: 114.6 | R10: 118.3 | S10: 112 | T10: 112.2 | U10: 110.4 | V10: 111.9 | W10: 109.7 | X10: 110.5 | Y10: 109.6 | Z10: 108.1 | AA10: 109.9 | AB10: 107.5 | AC10: 110.6 | AD10: 106.8 | AE10: 109 | AF10: 113.7
A11: Rural+Urban | B11: 2013 | C11: October | D11: 41548 | E11: =IF(D11<DATE(2020,3,1),"Pre-Covid","Post-Covid") -> Pre-Covid | F11: 117.1 | G11: 116.3 | H11: 113.3 | I11: 111.2 | J11: 105.7 | K11: 109.9 | L11: 171.2 | M11: 107.3 | N11: 102.7 | O11: 108.7 | P11: 111.2 | Q11: 115.4 | R11: 120.2 | S11: 112.5 | T11: 113.2 | U11: 111.2 | V11: 112.8 | W11: 110.5 | X11: 110.9 | Y11: 110.3 | Z11: 108.6 | AA11: 109.5 | AB11: 108.1 | AC11: 110.8 | AD11: 107.4 | AE11: 109.2 | AF11: 114.8
A12: Rural+Urban | B12: 2013 | C12: November | D12: 41579 | E12: =IF(D12<DATE(2020,3,1),"Pre-Covid","Post-Covid") -> Pre-Covid | F12: 118.1 | G12: 115.4 | H12: 118.7 | I12: 112.5 | J12: 106.8 | K12: 113.5 | L12: 183.1 | M12: 108.2 | N12: 102.2 | O12: 109.4 | P12: 111.8 | Q12: 116.5 | R12: 122.6 | S12: 113.1 | T12: 114.2 | U12: 111.9 | V12: 113.8 | W12: 111.1 | X12: 111.6 | Y12: 111.1 | Z12: 109.3 | AA12: 109.5 | AB12: 108.6 | AC12: 111.2 | AD12: 108.1 | AE12: 109.7 | AF12: 116.3
A13: Rural+Urban | B13: 2013 | C13: December | D13: 41609 | E13: =IF(D13<DATE(2020,3,1),"Pre-Covid","Post-Covid") -> Pre-Covid | F13: 119.1 | G13: 116.7 | H13: 123.5 | I13: 113.4 | J13: 107.3 | K13: 113.3 | L13: 145.4 | M13: 108.7 | N13: 101.5 | O13: 110.5 | P13: 112.1 | Q13: 117.4 | R13: 118.4 | S13: 114 | T13: 115.2 | U13: 112.7 | V13: 114.8 | W13: 110.7 | X13: 111.9 | Y13: 111.7 | Z13: 109.7 | AA13: 109.8 | AB13: 109 | AC13: 111.5 | AD13: 107.9 | AE13: 110 | AF13: 114.5
... A87: Rural+Urban | B87: 2020 | C87: March | D87: 43891 | E87: =IF(D87<DATE(2020,3,1),"Pre-Covid","Post-Covid") -> Post-Covid | F87: 145.1 | G87: 167 | H87: 148.1 | I87: 151.5 | J87: 131.2 | K87: 142.5 | L87: 157.3 | M87: 141.1 | N87: 113.2 | O87: 153.2 | P87: 136.7 | Q87: 159.6 | R87: 148.9 | S87: 171.2 | T87: 151.2 | U87: 141.9 | V87: 149.8 | W87: 154.5 | X87: 148.9 | Y87: 146.4 | Z87: 152.3 | AA87: 129.9 | AB87: 143.7 | AC87: 156.1 | AD87: 145.2 | AE87: 143.8 | AF87: 148.6
A88: Rural+Urban | B88: 2020 | C88: April | D88: 43922 | E88: =IF(D88<DATE(2020,3,1),"Pre-Covid","Post-Covid") -> Post-Covid | F88: 148.7 | H88: 148.8 | I88: 155.6 | J88: 135.1 | K88: 149.9 | L88: 168.6 | M88: 150.4 | N88: 120.3 | O88: 157.1 | P88: 136.8 | Q88: 137.37674 | R88: 151.4 | S88: 139.18721 | T88: 132.41395 | U88: 126.7686 | V88: 131.58953 | W88: 155.6 | X88: 144.1 | Y88: 126.9814 | Z88: 150.7 | AA88: 115.9314 | AB88: 122.86977 | AC88: 130.56744 | AD88: 120.18605 | AE88: 122.81395 | AF88: 128.57558
A89: Rural+Urban | B89: 2020 | C89: May | D89: 43952 | E89: =IF(D89<DATE(2020,3,1),"Pre-Covid","Post-Covid") -> Post-Covid | F89: 129.14483 | G89: 136.54419 | H89: 128.14598 | I89: 131.2908 | J89: 115.42759 | K89: 132.95747 | L89: 145.63218 | M89: 132.22989 | N89: 107.9092 | O89: 129.80575 | P89: 123.5046 | Q89: 137.37674 | R89: 131.81264 | S89: 139.18721 | T89: 132.41395 | U89: 126.7686 | V89: 131.58953 | W89: 128.85517 | X89: 125.94368 | Y89: 126.9814 | Z89: 126.27356 | AA89: 115.9314 | AB89: 122.86977 | AC89: 130.56744 | AD89: 120.18605 | AE89: 122.81395 | AF89: 128.57558
A90: Rural+Urban | B90: 2020 | C90: June | D90: 43983 | E90: =IF(D90<DATE(2020,3,1),"Pre-Covid","Post-Covid") -> Post-Covid | F90: 149.6 | G90: 192.7 | H90: 151.4 | I90: 153.3 | J90: 136.3 | K90: 147.2 | L90: 156.5 | M90: 150.9 | N90: 114.2 | O90: 159.5 | P90: 139.4 | Q90: 161.8 | R90: 154 | S90: 183.5 | T90: 152.5 | U90: 144.4 | V90: 151.4 | W90: 154.7 | X90: 141.9 | Y90: 146.4 | Z90: 154.4 | AA90: 135 | AB90: 148.3 | AC90: 156.4 | AD90: 151.6 | AE90: 147 | AF90: 151.8
A91: Rural+Urban | B91: 2020 | C91: July | D91: 44013 | E91: =IF(D91<DATE(2020,3,1),"Pre-Covid","Post-Covid") -> Post-Covid | F91: 149.6 | G91: 192.7 | H91: 151.4 | I91: 153.3 | J91: 136.3 | K91: 147.2 | L91: 156.5 | M91: 150.9 | N91: 114.2 | O91: 159.5 | P91: 139.4 | Q91: 161.8 | R91: 154 | S91: 183.5 | T91: 152.5 | U91: 144.4 | V91: 151.4 | W91: 154.7 | X91: 141.9 | Y91: 146.4 | Z91: 154.4 | AA91: 135 | AB91: 148.3 | AC91: 156.4 | AD91: 151.6 | AE91: 147 | AF91: 151.8
A92: Rural+Urban | B92: 2020 | C92: August | D92: 44044 | E92: =IF(D92<DATE(2020,3,1),"Pre-Covid","Post-Covid") -> Post-Covid | F92: 148.9 | G92: 190.9 | H92: 150.8 | I92: 153.3 | J92: 137.4 | K92: 150.4 | L92: 178.1 | M92: 150.4 | N92: 115.1 | O92: 160 | P92: 140.6 | Q92: 162.3 | R92: 157 | S92: 182.6 | T92: 153.1 | U92: 143.4 | V92: 151.7 | W92: 155.5 | X92: 143 | Y92: 148.4 | Z92: 155 | AA92: 138.5 | AB92: 146 | AC92: 158.5 | AD92: 154.3 | AE92: 149 | AF92: 153.9
A93: Rural+Urban | B93: 2020 | C93: September | D93: 44075 | E93: =IF(D93<DATE(2020,3,1),"Pre-Covid","Post-Covid") -> Post-Covid | F93: 148.4 | G93: 187.1 | H93: 152.5 | I93: 153.6 | J93: 138.2 | K93: 150.9 | L93: 186.7 | M93: 149.8 | N93: 116.4 | O93: 160.3 | P93: 142.2 | Q93: 162.9 | R93: 158 | S93: 184.4 | T93: 153.4 | U93: 144.3 | V93: 152 | W93: 156.3 | X93: 142.9 | Y93: 148.7 | Z93: 155.6 | AA93: 139.6 | AB93: 146.6 | AC93: 157.5 | AD93: 158.4 | AE93: 150 | AF93: 154.7
A94: Rural+Urban | B94: 2020 | C94: October | D94: 44105 | E94: =IF(D94<DATE(2020,3,1),"Pre-Covid","Post-Covid") -> Post-Covid | F94: 147.5 | G94: 188.9 | H94: 161.4 | I94: 153.6 | J94: 140.1 | K94: 151.2 | L94: 209.2 | M94: 150.9 | N94: 116.2 | O94: 161 | P94: 144 | Q94: 163.2 | R94: 161.4 | S94: 184.3 | T94: 153.7 | U94: 144.6 | V94: 152.3 | W94: 156.5 | X94: 143.1 | Y94: 148.7 | Z94: 156.3 | AA94: 140.6 | AB94: 146.5 | AC94: 158.5 | AD94: 157 | AE94: 150.4 | AF94: 156.4
A95: Rural+Urban | B95: 2020 | C95: November | D95: 44136 | E95: =IF(D95<DATE(2020,3,1),"Pre-Covid","Post-Covid") -> Post-Covid | F95: 146.8 | G95: 191 | H95: 173.6 | I95: 153.8 | J95: 142.7 | K95: 148.4 | L95: 230 | M95: 156.8 | N95: 115.7 | O95: 161.8 | P95: 146.5 | Q95: 163.8 | R95: 164.7 | S95: 184.8 | T95: 154.3 | U95: 144.9 | V95: 152.8 | W95: 158 | X95: 143.6 | Y95: 149.2 | Z95: 157.2 | AA95: 140.4 | AB95: 148.4 | AC95: 158.6 | AD95: 156.9 | AE95: 150.7 | AF95: 158.4
A96: Rural+Urban | B96: 2020 | C96: December | D96: 44166 | E96: =IF(D96<DATE(2020,3,1),"Pre-Covid","Post-Covid") -> Post-Covid | F96: 146 | G96: 191 | H96: 175.3 | I96: 154.1 | J96: 146.6 | K96: 147.7 | L96: 230.5 | M96: 160.2 | N96: 115.3 | O96: 163 | P96: 149.2 | Q96: 164.8 | R96: 165.4 | S96: 185.4 | T96: 155 | U96: 145.4 | V96: 153.6 | W96: 158.4 | X96: 144.6 | Y96: 149.7 | Z96: 158.3 | AA96: 140.7 | AB96: 148.5 | AC96: 159.4 | AD96: 157.1 | AE96: 151.2 | AF96: 158.9
A97: Rural+Urban | B97: 2021 | C97: January | D97: 44197 | E97: =IF(D97<DATE(2020,3,1),"Pre-Covid","Post-Covid") -> Post-Covid | F97: 144.9 | G97: 190.1 | H97: 175.3 | I97: 154.1 | J97: 150.9 | K97: 149.6 | L97: 194.2 | M97: 160.4 | N97: 114.6 | O97: 164 | P97: 151.8 | Q97: 165.6 | R97: 161 | S97: 186.5 | T97: 155.5 | U97: 146.1 | V97: 154.2 | W97: 157.7 | X97: 147.9 | Y97: 150 | Z97: 159.3 | AA97: 141.9 | AB97: 149.6 | AC97: 159.2 | AD97: 156.8 | AE97: 151.9 | AF97: 157.3
A98: Rural+Urban | B98: 2021 | C98: February | D98: 44228 | E98: =IF(D98<DATE(2020,3,1),"Pre-Covid","Post-Covid") -> Post-Covid | F98: 144.3 | G98: 186.5 | H98: 168.7 | I98: 154.7 | J98: 158.7 | K98: 150.7 | L98: 160 | M98: 158.8 | N98: 112.8 | O98: 164.2 | P98: 155.5 | Q98: 167.5 | R98: 156.9 | S98: 188.3 | T98: 157.2 | U98: 147.4 | V98: 155.8 | W98: 159.8 | X98: 152.4 | Y98: 150.9 | Z98: 161.3 | AA98: 145.1 | AB98: 151.5 | AC98: 159.5 | AD98: 155.8 | AE98: 153.4 | AF98: 156.6
A99: Rural+Urban | B99: 2021 | C99: March | D99: 44256 | E99: =IF(D99<DATE(2020,3,1),"Pre-Covid","Post-Covid") -> Post-Covid | F99: 144.1 | G99: 192.2 | H99: 163.8 | I99: 154.9 | J99: 163.9 | K99: 153.7 | L99: 149.5 | M99: 159.8 | N99: 112.6 | O99: 163.5 | P99: 156.5 | Q99: 168.2 | R99: 156.7 | S99: 188.1 | T99: 157.8 | U99: 147.9 | V99: 156.4 | W99: 159.9 | X99: 155.5 | Y99: 151.2 | Z99: 161.7 | AA99: 146.2 | AB99: 152.6 | AC99: 160.2 | AD99: 153.8 | AE99: 153.8 | AF99: 156.8
A100: Rural+Urban | B100: 2021 | C100: April | D100: 44287 | E100: =IF(D100<DATE(2020,3,1),"Pre-Covid","Post-Covid") -> Post-Covid | F100: 144.3 | G100: 198 | H100: 164.6 | I100: 155.4 | J100: 170.1 | K100: 164.4 | L100: 144.1 | M100: 161.7 | N100: 113.1 | O100: 163.9 | P100: 157.6 | Q100: 168.9 | R100: 158 | S100: 188.8 | T100: 158.8 | U100: 148.5 | V100: 157.3 | W100: 161.4 | X100: 155.6 | Y100: 151.8 | Z100: 162.3 | AA100: 146.6 | AB100: 153.2 | AC100: 160.3 | AD100: 155.4 | AE100: 154.4 | AF100: 157.8
... A125: Rural+Urban | B125: 2023 | C125: May | D125: 45047 | E125: =IF(D125<DATE(2020,3,1),"Pre-Covid","Post-Covid") -> Post-Covid | F125: 173.7 | G125: 214.3 | H125: 173.2 | I125: 179.5 | J125: 170 | K125: 172.2 | L125: 161 | M125: 175.6 | N125: 122.7 | O125: 218 | P125: 173.4 | Q125: 194.2 | R125: 179.1 | S125: 201 | T125: 187.3 | U125: 179.7 | V125: 186.2 | W125: 175.6 | X125: 182.8 | Y125: 175.2 | Z125: 185.7 | AA125: 164.8 | AB125: 171.2 | AC125: 177.1 | AD125: 185.2 | AE125: 175.7 | AF125: 179.1

Sheet  Broder Category Data 
A1: Broder Category Mapping | E1: Broder Category CPI inflation index
A3: CPI Sub-Category | B3: Broader Category | E3: Sector | F3: Year | G3: Month | H3: Date | I3: Covid Period | J3: Food and beverages | K3: Pan, tobacco and intoxicants | L3: Clothing and footwear | M3: Housing | N3: Fuel and light | O3: Education | P3: Health | Q3: Transport and communication | R3: Miscellaneous | S3: General index | U3: Note-
A4: Cereals and products | B4: Food | E4: Rural+Urban | F4: 2013 | G4: January | H4: 41275 | I4: =IF(H4<DATE(2020,3,1),"Pre-Covid","Post-Covid") -> Pre-Covid | J4: 105.6 | K4: 105.1 | L4: 106.2 | M4: 100.3 | N4: 105.5 | O4: 103.6 | P4: 104 | Q4: 103.2 | R4: 104.13333 | S4: 104.6 | U4: 1. In this Miscellaneous is calculated by doing Average of Household goods and services, Recreation and amusement, Personal care and effects Columns from the main data.
A5: Meat and fish | B5: Food | E5: Rural+Urban | F5: 2013 | G5: February | H5: 41306 | I5: =IF(H5<DATE(2020,3,1),"Pre-Covid","Post-Covid") -> Pre-Covid | J5: 106.6 | K5: 105.7 | L5: 106.8 | M5: 100.4 | N5: 106 | O5: 103.9 | P5: 104.5 | Q5: 104.2 | R5: 104.43333 | S5: 105.3
A6: Egg | B6: Food | E6: Rural+Urban | F6: 2013 | G6: March | H6: 41334 | I6: =IF(H6<DATE(2020,3,1),"Pre-Covid","Post-Covid") -> Pre-Covid | J6: 106.9 | K6: 106.6 | L6: 107.3 | M6: 100.4 | N6: 106.1 | O6: 104 | P6: 104.9 | Q6: 105.1 | R6: 104.53333 | S6: 105.5
A7: Milk and products | B7: Food | E7: Rural+Urban | F7: 2013 | G7: April | H7: 41365 | I7: =IF(H7<DATE(2020,3,1),"Pre-Covid","Post-Covid") -> Pre-Covid | J7: 107.7 | K7: 107.5 | L7: 107.9 | M7: 100.5 | N7: 106.5 | O7: 105 | P7: 105.3 | Q7: 104.7 | R7: 104.46667 | S7: 106.1
A8: Oils and fats | B8: Food | E8: Rural+Urban | F8: 2013 | G8: May | H8: 41395 | I8: =IF(H8<DATE(2020,3,1),"Pre-Covid","Post-Covid") -> Pre-Covid | J8: 109.2 | K8: 108.6 | L8: 108.5 | M8: 100.5 | N8: 107.4 | O8: 105.6 | P8: 105.9 | Q8: 104 | R8: 104.66667 | S8: 106.9
A9: Fruits | B9: Food | E9: Rural+Urban | F9: 2013 | G9: June | H9: 41426 | I9: =IF(H9<DATE(2020,3,1),"Pre-Covid","Post-Covid") -> Pre-Covid | J9: 112.2 | K9: 109.5 | L9: 109.3 | M9: 106.6 | N9: 108.3 | O9: 107.4 | P9: 106.4 | Q9: 105.1 | R9: 105.26667 | S9: 109.3
A10: Vegetables | B10: Food | E10: Rural+Urban | F10: 2013 | G10: July | H10: 41456 | I10: =IF(H10<DATE(2020,3,1),"Pre-Covid","Post-Covid") -> Pre-Covid | J10: 114.7 | K10: 110.3 | L10: 110 | M10: 107.7 | N10: 109.2 | O10: 109.1 | P10: 107 | Q10: 107.1 | R10: 105.7 | S10: 111
A11: Pulses and products | B11: Food | E11: Rural+Urban | F11: 2013 | G11: August | H11: 41487 | I11: =IF(H11<DATE(2020,3,1),"Pre-Covid","Post-Covid") -> Pre-Covid | J11: 116.6 | K11: 111.2 | L11: 110.7 | M11: 108.9 | N11: 109.7 | O11: 109.9 | P11: 107.5 | Q11: 108 | R11: 106.9 | S11: 112.4
A12: Sugar and Confectionery | B12: Food | E12: Rural+Urban | F12: 2013 | G12: September | H12: 41518 | I12: =IF(H12<DATE(2020,3,1),"Pre-Covid","Post-Covid") -> Pre-Covid | J12: 118.3 | K12: 112 | L12: 111.9 | M12: 109.7 | N12: 110.5 | O12: 110.6 | P12: 108.1 | Q12: 109.9 | R12: 107.96667 | S12: 113.7
A13: Spices | B13: Food | E13: Rural+Urban | F13: 2013 | G13: October | H13: 41548 | I13: =IF(H13<DATE(2020,3,1),"Pre-Covid","Post-Covid") -> Pre-Covid | J13: 120.2 | K13: 112.5 | L13: 112.8 | M13: 110.5 | N13: 110.9 | O13: 110.8 | P13: 108.6 | Q13: 109.5 | R13: 108.6 | S13: 114.8
A14: Non-alcoholic beverages | B14: Food | E14: Rural+Urban | F14: 2013 | G14: November | H14: 41579 | I14: =IF(H14<DATE(2020,3,1),"Pre-Covid","Post-Covid") -> Pre-Covid | J14: 122.6 | K14: 113.1 | L14: 113.8 | M14: 111.1 | N14: 111.6 | O14: 111.2 | P14: 109.3 | Q14: 109.5 | R14: 109.26667 | S14: 116.3
A15: Prepared meals, snacks, sweets etc. | B15: Food | E15: Rural+Urban | F15: 2013 | G15: December | H15: 41609 | I15: =IF(H15<DATE(2020,3,1),"Pre-Covid","Post-Covid") -> Pre-Covid | J15: 118.4 | K15: 114 | L15: 114.8 | M15: 110.7 | N15: 111.9 | O15: 111.5 | P15: 109.7 | Q15: 109.8 | R15: 109.53333 | S15: 114.5
A16: Food and beverages | B16: Food | E16: Rural+Urban | F16: 2014 | G16: January | H16: 41640 | I16: =IF(H16<DATE(2020,3,1),"Pre-Covid","Post-Covid") -> Pre-Covid | J16: 115.8 | K16: 114.5 | L16: 115.4 | M16: 111.6 | N16: 112.2 | O16: 111.6 | P16: 110.3 | Q16: 110.7 | R16: 110.06667 | S16: 113.6
... A30: General index | B30: General index | E30: Rural+Urban | F30: 2015 | G30: March | H30: 42064 | I30: =IF(H30<DATE(2020,3,1),"Pre-Covid","Post-Covid") -> Pre-Covid | J30: 123.4 | K30: 125.8 | L30: 123.7 | M30: 118.6 | N30: 118.3 | O30: 120.1 | P30: 116.7 | Q30: 109.9 | R30: 115.2 | S30: 120.2
E31: Rural+Urban | F31: 2015 | G31: April | H31: 42095 | I31: =IF(H31<DATE(2020,3,1),"Pre-Covid","Post-Covid") -> Pre-Covid | J31: 124 | K31: 126.9 | L31: 124.1 | M31: 119.2 | N31: 118.7 | O31: 121 | P31: 117.1 | Q31: 110.1 | R31: 115.76667 | S31: 120.7
E32: Rural+Urban | F32: 2015 | G32: May | H32: 42125 | I32: =IF(H32<DATE(2020,3,1),"Pre-Covid","Post-Covid") -> Pre-Covid | J32: 125 | K32: 127.9 | L32: 124.7 | M32: 119.6 | N32: 119.2 | O32: 121.4 | P32: 117.7 | Q32: 112 | R32: 116.26667 | S32: 121.6
E33: Rural+Urban | F33: 2015 | G33: June | H33: 42156 | I33: =IF(H33<DATE(2020,3,1),"Pre-Covid","Post-Covid") -> Pre-Covid | J33: 127.3 | K33: 129.2 | L33: 125.7 | M33: 119 | N33: 119.8 | O33: 123.1 | P33: 118.5 | Q33: 112.9 | R33: 116.93333 | S33: 123
E34: Rural+Urban | F34: 2015 | G34: July | H34: 42186 | I34: =IF(H34<DATE(2020,3,1),"Pre-Covid","Post-Covid") -> Pre-Covid | J34: 128.2 | K34: 130.4 | L34: 126.1 | M34: 119.9 | N34: 120.1 | O34: 124.4 | P34: 119 | Q34: 112.7 | R34: 116.93333 | S34: 123.6
E35: Rural+Urban | F35: 2015 | G35: August | H35: 42217 | I35: =IF(H35<DATE(2020,3,1),"Pre-Covid","Post-Covid") -> Pre-Covid | J35: 130.3 | K35: 131.2 | L35: 126.6 | M35: 120.9 | N35: 120.6 | O35: 125.1 | P35: 119.4 | Q35: 111.7 | R35: 117.36667 | S35: 124.8
E36: Rural+Urban | F36: 2015 | G36: September | H36: 42248 | I36: =IF(H36<DATE(2020,3,1),"Pre-Covid","Post-Covid") -> Pre-Covid | J36: 131.2 | K36: 132 | L36: 127.2 | M36: 121.6 | N36: 120.4 | O36: 125.7 | P36: 119.8 | Q36: 111.3 | R36: 118.1 | S36: 125.4
E37: Rural+Urban | F37: 2015 | G37: October | H37: 42278 | I37: =IF(H37<DATE(2020,3,1),"Pre-Covid","Post-Covid") -> Pre-Covid | J37: 132.1 | K37: 132.5 | L37: 127.8 | M37: 122.4 | N37: 120.8 | O37: 125.9 | P37: 120.4 | Q37: 111.4 | R37: 118.53333 | S37: 126.1
E38: Rural+Urban | F38: 2015 | G38: November | H38: 42309 | I38: =IF(H38<DATE(2020,3,1),"Pre-Covid","Post-Covid") -> Pre-Covid | J38: 132.7 | K38: 133.6 | L38: 128.6 | M38: 122.9 | N38: 121.6 | O38: 126.3 | P38: 120.9 | Q38: 111.5 | R38: 118.8 | S38: 126.6
E39: Rural+Urban | F39: 2015 | G39: December | H39: 42339 | I39: =IF(H39<DATE(2020,3,1),"Pre-Covid","Post-Covid") -> Pre-Covid | J39: 131.4 | K39: 134.5 | L39: 129 | M39: 122.4 | N39: 122 | O39: 126.2 | P39: 121.4 | Q39: 111.5 | R39: 118.96667 | S39: 126.1
E40: Rural+Urban | F40: 2016 | G40: January | H40: 42370 | I40: =IF(H40<DATE(2020,3,1),"Pre-Covid","Post-Covid") -> Pre-Covid | J40: 131.3 | K40: 135.2 | L40: 129.5 | M40: 123.4 | N40: 122.7 | O40: 126.3 | P40: 122 | Q40: 111.1 | R40: 119.5 | S40: 126.3
E41: Rural+Urban | F41: 2016 | G41: February | H41: 42401 | I41: =IF(H41<DATE(2020,3,1),"Pre-Covid","Post-Covid") -> Pre-Covid | J41: 129.9 | K41: 135.9 | L41: 130.2 | M41: 124.4 | N41: 123.1 | O41: 126.6 | P41: 122.5 | Q41: 111.4 | R41: 120.5 | S41: 126
E42: Rural+Urban | F42: 2016 | G42: March | H42: 42430 | I42: =IF(H42<DATE(2020,3,1),"Pre-Covid","Post-Covid") -> Pre-Covid | J42: 129.8 | K42: 136.5 | L42: 130.5 | M42: 124.9 | N42: 122.4 | O42: 126.9 | P42: 122.9 | Q42: 110.9 | R42: 121 | S42: 126
... E127: Rural+Urban | F127: 2023 | G127: May | H127: 45047 | I127: =IF(H127<DATE(2020,3,1),"Pre-Covid","Post-Covid") -> Post-Covid | J127: 179.1 | K127: 201 | L127: 186.2 | M127: 175.6 | N127: 182.8 | O127: 177.1 | P127: 185.7 | Q127: 164.8 | R127: 177.2 | S127: 179.1

Sheet Question 1
A1: QUESTION 1: Contribution of Broader Categories (Latest Month)
A3: Sector | B3: Year | C3: Month | D3: Date | E3: Covid Period | F3: Cereals and products | G3: Meat and fish | H3: Egg | I3: Milk and products | J3: Oils and fats | K3: Fruits | L3: Vegetables | M3: Pulses and products | N3: Sugar and Confectionery | O3: Spices | P3: Non-alcoholic beverages | Q3: Prepared meals, snacks, sweets etc. | R3: Food and beverages | S3: Pan, tobacco and intoxicants | T3: Clothing | U3: Footwear | V3: Clothing and footwear | W3: Housing | X3: Fuel and light | Y3: Household goods and services | Z3: Health | AA3: Transport and communication | AB3: Recreation and amusement | AC3: Education | AD3: Personal care and effects | AE3: Miscellaneous | AF3: General index
A4: Rural+Urban | B4: 2023 | C4: May | D4: 45047 | E4: Post-Covid | F4: 173.7 | G4: 214.3 | H4: 173.2 | I4: 179.5 | J4: 170 | K4: 172.2 | L4: 161 | M4: 175.6 | N4: 122.7 | O4: 218 | P4: 173.4 | Q4: 194.2 | R4: 179.1 | S4: 201 | T4: 187.3 | U4: 179.7 | V4: 186.2 | W4: 175.6 | X4: 182.8 | Y4: 175.2 | Z4: 185.7 | AA4: 164.8 | AB4: 171.2 | AC4: 177.1 | AD4: 185.2 | AE4: 175.7 | AF4: 179.1
A8: Category | B8: Bucket Value (Sum of Indices) | C8: Contribution %
A9: Food | B9: =SUM(F4,G4,H4,I4,J4,K4,L4,M4,N4,O4,P4,Q4) -> 2127.8 | C9: =B9/SUM($B$9:$B$17) -> 0.51728497
A10: Pan, tobacco and intoxicants | B10: 201 | C10: =B10/SUM($B$9:$B$17) -> 0.048864686
A11: Clothing & Footwear | B11: =SUM(T4,U4) -> 367 | C11: =B11/SUM($B$9:$B$17) -> 0.089220596
A12: Health | B12: 185.7 | C12: =B12/SUM($B$9:$B$17) -> 0.045145135
A13: Energy | B13: 182.8 | C13: =B13/SUM($B$9:$B$17) -> 0.044440123
A14: Education | B14: 177.1 | C14: =B14/SUM($B$9:$B$17) -> 0.043054408
A15: Housing | B15: 175.6 | C15: =B15/SUM($B$9:$B$17) -> 0.042689746
A16: Transportation | B16: 164.8 | C16: =B16/SUM($B$9:$B$17) -> 0.04006418
A17: Miscellaneous | B17: =SUM(Y4,AB4,AD4) -> 531.6 | C17: =B17/SUM($B$9:$B$17) -> 0.12923616
A18: Total | B18: =SUM(B9:B17) -> 4113.4 | C18: =B18/SUM($B$9:$B$17) -> 1
E20: Conclusion-
E21: Highest Contributor: The Food category has the highest contribution towards the CPI calculation at 51.73%.

Sheet Question 2
A1: Sector | B1: Year | C1: Month | D1: Date | E1: Covid Period | F1: General index | I1: Sector | J1: Year | K1: General index | L1: YoY Inflation Rate
A2: Rural+Urban | B2: 2013 | C2: January | D2: 41275 | E2: Pre-Covid | F2: 104.6 | I2: Rural+Urban | J2: 2017 | K2: =AVERAGEIF($B$2:$B$125,J2,$F$2:$F$125) -> 133.5
A3: Rural+Urban | B3: 2013 | C3: February | D3: 41306 | E3: Pre-Covid | F3: 105.3 | I3: Rural+Urban | J3: 2018 | K3: =AVERAGEIF($B$2:$B$125,J3,$F$2:$F$125) -> 138.775 | L3: =(K3-K2)/K2*100 -> 3.9513109
A4: Rural+Urban | B4: 2013 | C4: March | D4: 41334 | E4: Pre-Covid | F4: 105.5 | I4: Rural+Urban | J4: 2019 | K4: =AVERAGEIF($B$2:$B$125,J4,$F$2:$F$125) -> 144.18182 | L4: =(K4-K3)/K3*100 -> 3.8961039
A5: Rural+Urban | B5: 2013 | C5: April | D5: 41365 | E5: Pre-Covid | F5: 106.1 | I5: Rural+Urban | J5: 2020 | K5: =AVERAGEIF($B$2:$B$125,J5,$F$2:$F$125) -> 151.08825 | L5: =(K5-K4)/K4*100 -> 4.7900861
A6: Rural+Urban | B6: 2013 | C6: May | D6: 41395 | E6: Pre-Covid | F6: 106.9 | I6: Rural+Urban | J6: 2021 | K6: =AVERAGEIF($B$2:$B$125,J6,$F$2:$F$125) -> 161.45833 | L6: =(K6-K5)/K5*100 -> 6.8635926
A7: Rural+Urban | B7: 2013 | C7: June | D7: 41426 | E7: Pre-Covid | F7: 109.3 | I7: Rural+Urban | J7: 2022 | K7: =AVERAGEIF($B$2:$B$125,J7,$F$2:$F$125) -> 172.15 | L7: =(K7-K6)/K6*100 -> 6.6219355
A8: Rural+Urban | B8: 2013 | C8: July | D8: 41456 | E8: Pre-Covid | F8: 111 | I8: Rural+Urban | J8: 2023 | K8: =AVERAGEIF($B$2:$B$125,J8,$F$2:$F$125) -> 177.62 | L8: =(K8-K7)/K7*100 -> 3.1774615
A9: Rural+Urban | B9: 2013 | C9: August | D9: 41487 | E9: Pre-Covid | F9: 112.4
A10: Rural+Urban | B10: 2013 | C10: September | D10: 41518 | E10: Pre-Covid | F10: 113.7
A11: Rural+Urban | B11: 2013 | C11: October | D11: 41548 | E11: Pre-Covid | F11: 114.8
A12: Rural+Urban | B12: 2013 | C12: November | D12: 41579 | E12: Pre-Covid | F12: 116.3
A13: Rural+Urban | B13: 2013 | C13: December | D13: 41609 | E13: Pre-Covid | F13: 114.5
A14: Rural+Urban | B14: 2014 | C14: January | D14: 41640 | E14: Pre-Covid | F14: 113.6
A15: Rural+Urban | B15: 2014 | C15: February | D15: 41671 | E15: Pre-Covid | F15: 113.6
A16: Rural+Urban | B16: 2014 | C16: Marcrh | D16: 41699 | E16: Pre-Covid | F16: 114.2
A17: Rural+Urban | B17: 2014 | C17: April | D17: 41730 | E17: Pre-Covid | F17: 115.1
A18: Rural+Urban | B18: 2014 | C18: May | D18: 41760 | E18: Pre-Covid | F18: 115.8
A19: Rural+Urban | B19: 2014 | C19: June | D19: 41791 | E19: Pre-Covid | F19: 116.7
A20: Rural+Urban | B20: 2014 | C20: July | D20: 41821 | E20: Pre-Covid | F20: 119.2
... A24: Rural+Urban | B24: 2014 | C24: November | D24: 41944 | E24: Pre-Covid | F24: 120.1
A25: Rural+Urban | B25: 2014 | D25: 41974 | E25: Pre-Covid | F25: 119.4
A26: Rural+Urban | B26: 2015 | C26: January | D26: 42005 | E26: Pre-Covid | F26: 119.5
A27: Rural+Urban | B27: 2015 | C27: February | D27: 42036 | E27: Pre-Covid | F27: 119.7
A28: Rural+Urban | B28: 2015 | C28: March | D28: 42064 | E28: Pre-Covid | F28: 120.2
A29: Rural+Urban | B29: 2015 | C29: April | D29: 42095 | E29: Pre-Covid | F29: 120.7
A30: Rural+Urban | B30: 2015 | C30: May | D30: 42125 | E30: Pre-Covid | F30: 121.6
A31: Rural+Urban | B31: 2015 | C31: June | D31: 42156 | E31: Pre-Covid | F31: 123
A32: Rural+Urban | B32: 2015 | D32: 42186 | E32: Pre-Covid | F32: 123.6
A33: Rural+Urban | B33: 2015 | C33: August | D33: 42217 | E33: Pre-Covid | F33: 124.8
A34: Rural+Urban | B34: 2015 | C34: September | D34: 42248 | E34: Pre-Covid | F34: 125.4
A35: Rural+Urban | B35: 2015 | C35: October | D35: 42278 | E35: Pre-Covid | F35: 126.1
A36: Rural+Urban | B36: 2015 | C36: November | D36: 42309 | E36: Pre-Covid | F36: 126.6
A37: Rural+Urban | B37: 2015 | C37: December | D37: 42339 | E37: Pre-Covid | F37: 126.1
A38: Rural+Urban | B38: 2016 | C38: January | D38: 42370 | E38: Pre-Covid | F38: 126.3
A39: Rural+Urban | B39: 2016 | C39: February | D39: 42401 | E39: Pre-Covid | F39: 126
A40: Rural+Urban | B40: 2016 | C40: March | D40: 42430 | E40: Pre-Covid | F40: 126
A41: Rural+Urban | B41: 2016 | C41: April | D41: 42461 | E41: Pre-Covid | F41: 127.3
A42: Rural+Urban | B42: 2016 | C42: May | D42: 42491 | E42: Pre-Covid | F42: 128.6
A43: Rural+Urban | B43: 2016 | C43: June | D43: 42522 | E43: Pre-Covid | F43: 130.1
...

Sheet Question 3(A)
A1: A. Trend Analysis: Broader Food & Beverages Category
A3: Sector | B3: Year | C3: Month | D3: Date | E3: Covid Period | F3: Food and beverages | G3: MoM Inflation Rate | J3: Conclusions -
A4: Rural+Urban | B4: 2022 | C4: June | D4: 44713 | E4: =IF(D4<DATE(2020,3,1),"Pre-Covid","Post-Covid") -> Post-Covid | F4: 174.9
A5: Rural+Urban | B5: 2022 | C5: July | D5: 44743 | E5: =IF(D5<DATE(2020,3,1),"Pre-Covid","Post-Covid") -> Post-Covid | F5: 175 | G5: =(F5-F4)/F4 -> 0.00057175529 | J5: 1. Highest food inflation (MoM):
A6: Rural+Urban | B6: 2022 | C6: August | D6: 44774 | E6: =IF(D6<DATE(2020,3,1),"Pre-Covid","Post-Covid") -> Post-Covid | F6: 176.3 | G6: =(F6-F5)/F5 -> 0.0074285714 | J6: October 2022 (+1.01)
A7: Rural+Urban | B7: 2022 | C7: September | D7: 44805 | E7: =IF(D7<DATE(2020,3,1),"Pre-Covid","Post-Covid") -> Post-Covid | F7: 177.8 | G7: =(F7-F6)/F6 -> 0.0085082246
A8: Rural+Urban | B8: 2022 | C8: October | D8: 44835 | E8: =IF(D8<DATE(2020,3,1),"Pre-Covid","Post-Covid") -> Post-Covid | F8: 179.6 | G8: =(F8-F7)/F7 -> 0.010123735 | J8: 2. Lowest food inflation (MoM):
A9: Rural+Urban | B9: 2022 | C9: November | D9: 44866 | E9: =IF(D9<DATE(2020,3,1),"Pre-Covid","Post-Covid") -> Post-Covid | F9: 178.3 | G9: =(F9-F8)/F8 -> -0.0072383073 | J9: December 2022 (−1.35%)
A10: Rural+Urban | B10: 2022 | C10: December | D10: 44896 | E10: =IF(D10<DATE(2020,3,1),"Pre-Covid","Post-Covid") -> Post-Covid | F10: 175.9 | G10: =(F10-F9)/F9 -> -0.01346046
A11: Rural+Urban | B11: 2023 | C11: January | D11: 44927 | E11: =IF(D11<DATE(2020,3,1),"Pre-Covid","Post-Covid") -> Post-Covid | F11: 176.7 | G11: =(F11-F10)/F10 -> 0.0045480387
A12: Rural+Urban | B12: 2023 | C12: February | D12: 44958 | E12: =IF(D12<DATE(2020,3,1),"Pre-Covid","Post-Covid") -> Post-Covid | F12: 177 | G12: =(F12-F11)/F11 -> 0.0016977929
A13: Rural+Urban | B13: 2023 | C13: March | D13: 44986 | E13: =IF(D13<DATE(2020,3,1),"Pre-Covid","Post-Covid") -> Post-Covid | F13: 177 | G13: =(F13-F12)/F12 -> 0
A14: Rural+Urban | B14: 2023 | C14: April | D14: 45017 | E14: =IF(D14<DATE(2020,3,1),"Pre-Covid","Post-Covid") -> Post-Covid | F14: 177.9 | G14: =(F14-F13)/F13 -> 0.0050847458
A15: Rural+Urban | B15: 2023 | C15: May | D15: 45047 | E15: =IF(D15<DATE(2020,3,1),"Pre-Covid","Post-Covid") -> Post-Covid | F15: 179.1 | G15: =(F15-F14)/F14 -> 0.0067453626

Sheet Question 3(B)
A1: B. Absolute Change in Food Inflation (June 22 → May 23)
A3: Food Sub Category | B3: Cereals and products | C3: Meat and fish | D3: Egg | E3: Milk and products | F3: Oils and fats | G3: Fruits | H3: Vegetables | I3: Pulses and products | J3: Sugar and Confectionery | K3: Spices | L3: Non-alcoholic beverages | M3: Prepared meals, snacks, sweets etc.
A4: CPI Index (June 2022) | B4: 155 | C4: 219.4 | D4: 170.8 | E4: 165.8 | F4: 200.9 | G4: 169.7 | H4: 182.3 | I4: 164.3 | J4: 119.9 | K4: 187.1 | L4: 167.9 | M4: 183.9
A5: CPI Index (May 2023) | B5: 173.7 | C5: 214.3 | D5: 173.2 | E5: 179.5 | F5: 170 | G5: 172.2 | H5: 161 | I5: 175.6 | J5: 122.7 | K5: 218 | L5: 173.4 | M5: 194.2
A6: Absolute Change | B6: =B5-B4 -> 18.7 | C6: =C5-C4 -> -5.1 | D6: =D5-D4 -> 2.4 | E6: =E5-E4 -> 13.7 | F6: =F5-F4 -> -30.9 | G6: =G5-G4 -> 2.5 | H6: =H5-H4 -> -21.3 | I6: =I5-I4 -> 11.3 | ... M6: =M5-M4 -> 10.3
A8: 📌 Conclusion:
A9: 1. Biggest Individual Contributor (Within Food Category) is the Spices with the Highest absolute Increase of +30.9 Index Points
A10: 2. Even though prices of vegetables and cooking oil went down, prices of spices, cereals, and milk kept increasing. Because of this, they were the main reasons for the rise in food inflation.

Sheet Question 4 (Data)
A1: Data Required for Question 4
A3: Sector | B3: Year | C3: Month | D3: Date | E3: Covid Period | F3: Food and beverages | G3: Health | H3: Essential Servises | I3: General index | L3: Note-
A4: Rural+Urban | B4: 2013 | C4: January | D4: 41275 | E4: =IF(D4<DATE(2020,3,1),"Pre-Covid","Post-Covid") -> Pre-Covid | F4: 105.6 | G4: 104 | H4: =AVERAGE(' Broder Category Data '!M4,' Broder Category Data '!N4,' Broder Category Data '!O4,' Broder Category Data '!Q4) -> 103.15 | I4: 104.6 | L4: Essential Services is computed by Averaging columns like Housing, Transportation, Education, Fuel & Light form the Broder Category Data Sheet.
A5: Rural+Urban | B5: 2013 | C5: February | D5: 41306 | E5: =IF(D5<DATE(2020,3,1),"Pre-Covid","Post-Covid") -> Pre-Covid | F5: 106.6 | G5: 104.5 | H5: =AVERAGE(' Broder Category Data '!M5,' Broder Category Data '!N5,' Broder Category Data '!O5,' Broder Category Data '!Q5) -> 103.625 | I5: 105.3
A6: Rural+Urban | B6: 2013 | C6: March | D6: 41334 | E6: =IF(D6<DATE(2020,3,1),"Pre-Covid","Post-Covid") -> Pre-Covid | F6: 106.9 | G6: 104.9 | H6: =AVERAGE(' Broder Category Data '!M6,' Broder Category Data '!N6,' Broder Category Data '!O6,' Broder Category Data '!Q6) -> 103.9 | I6: 105.5
A7: Rural+Urban | B7: 2013 | C7: April | D7: 41365 | E7: =IF(D7<DATE(2020,3,1),"Pre-Covid","Post-Covid") -> Pre-Covid | F7: 107.7 | G7: 105.3 | H7: =AVERAGE(' Broder Category Data '!M7,' Broder Category Data '!N7,' Broder Category Data '!O7,' Broder Category Data '!Q7) -> 104.175 | I7: 106.1
A8: Rural+Urban | B8: 2013 | C8: May | D8: 41395 | E8: =IF(D8<DATE(2020,3,1),"Pre-Covid","Post-Covid") -> Pre-Covid | F8: 109.2 | G8: 105.9 | H8: =AVERAGE(' Broder Category Data '!M8,' Broder Category Data '!N8,' Broder Category Data '!O8,' Broder Category Data '!Q8) -> 104.375 | I8: 106.9
A9: Rural+Urban | B9: 2013 | C9: June | D9: 41426 | E9: =IF(D9<DATE(2020,3,1),"Pre-Covid","Post-Covid") -> Pre-Covid | F9: 112.2 | G9: 106.4 | H9: =AVERAGE(' Broder Category Data '!M9,' Broder Category Data '!N9,' Broder Category Data '!O9,' Broder Category Data '!Q9) -> 106.85 | I9: 109.3
A10: Rural+Urban | B10: 2013 | C10: July | D10: 41456 | E10: =IF(D10<DATE(2020,3,1),"Pre-Covid","Post-Covid") -> Pre-Covid | F10: 114.7 | G10: 107 | H10: =AVERAGE(' Broder Category Data '!M10,' Broder Category Data '!N10,' Broder Category Data '!O10,' Broder Category Data '!Q10) -> 108.275 | I10: 111
A11: Rural+Urban | B11: 2013 | C11: August | D11: 41487 | E11: =IF(D11<DATE(2020,3,1),"Pre-Covid","Post-Covid") -> Pre-Covid | F11: 116.6 | G11: 107.5 | H11: =AVERAGE(' Broder Category Data '!M11,' Broder Category Data '!N11,' Broder Category Data '!O11,' Broder Category Data '!Q11) -> 109.125 | I11: 112.4
A12: Rural+Urban | B12: 2013 | C12: September | D12: 41518 | E12: =IF(D12<DATE(2020,3,1),"Pre-Covid","Post-Covid") -> Pre-Covid | F12: 118.3 | G12: 108.1 | H12: =AVERAGE(' Broder Category Data '!M12,' Broder Category Data '!N12,' Broder Category Data '!O12,' Broder Category Data '!Q12) -> 110.175 | I12: 113.7
A13: Rural+Urban | B13: 2013 | C13: October | D13: 41548 | E13: =IF(D13<DATE(2020,3,1),"Pre-Covid","Post-Covid") -> Pre-Covid | F13: 120.2 | G13: 108.6 | H13: =AVERAGE(' Broder Category Data '!M13,' Broder Category Data '!N13,' Broder Category Data '!O13,' Broder Category Data '!Q13) -> 110.425 | I13: 114.8
A14: Rural+Urban | B14: 2013 | C14: November | D14: 41579 | E14: =IF(D14<DATE(2020,3,1),"Pre-Covid","Post-Covid") -> Pre-Covid | F14: 122.6 | G14: 109.3 | H14: =AVERAGE(' Broder Category Data '!M14,' Broder Category Data '!N14,' Broder Category Data '!O14,' Broder Category Data '!Q14) -> 110.85 | I14: 116.3
A15: Rural+Urban | B15: 2013 | C15: December | D15: 41609 | E15: =IF(D15<DATE(2020,3,1),"Pre-Covid","Post-Covid") -> Pre-Covid | F15: 118.4 | G15: 109.7 | H15: =AVERAGE(' Broder Category Data '!M15,' Broder Category Data '!N15,' Broder Category Data '!O15,' Broder Category Data '!Q15) -> 110.975 | I15: 114.5
A16: Rural+Urban | B16: 2014 | C16: January | D16: 41640 | E16: =IF(D16<DATE(2020,3,1),"Pre-Covid","Post-Covid") -> Pre-Covid | F16: 115.8 | G16: 110.3 | H16: =AVERAGE(' Broder Category Data '!M16,' Broder Category Data '!N16,' Broder Category Data '!O16,' Broder Category Data '!Q16) -> 111.525 | I16: 113.6
... A127: Rural+Urban | B127: 2023 | C127: May | D127: 45017 | E127: =IF(D127<DATE(2020,3,1),"Pre-Covid","Post-Covid") -> Post-Covid | F127: 179.1 | G127: 185.7 | H127: =AVERAGE(' Broder Category Data '!M127,' Broder Category Data '!N127,' Broder Category Data '!O127,' Broder Category Data '!Q127) -> 175.075 | I127: 179.1

Sheet Question 4 Solution
A1: YoY Inflation % | K1: Avg Inflation (%) for years 2019,2020,2021
A3: Year | B3: Month | C3: Date | D3: Covid Period | E3: Food and beverages | F3: Health Care | G3: Essential Sevices | H3: General | K3: Category | L3: 2019 | M3: 2020 | N3: 2021
A4: 2014 | B4: January | C4: 41640 | D4: =IF(C4<DATE(2020,3,1),"Pre-Covid","Post-Covid") -> Pre-Covid | E4: =('Question 4 (Data)'!F16-'Question 4 (Data)'!F4)/'Question 4 (Data)'!F4 -> 0.096590909 | F4: =('Question 4 (Data)'!G16-'Question 4 (Data)'!G4)/'Question 4 (Data)'!G4 -> 0.060576923 | G4: =('Question 4 (Data)'!H16-'Question 4 (Data)'!H4)/'Question 4 (Data)'!H4 -> 0.081192438 | H4: =('Question 4 (Data)'!I16-'Question 4 (Data)'!I4)/'Question 4 (Data)'!I4 -> 0.086042065 | K4: Food and beverages | L4: =AVERAGEIF($A$4:$A$115,L3,$E$4:$E$115) -> 0.038233052 | M4: =AVERAGEIF($A$4:$A$115,M3,$E$4:$E$115) -> 0.076667233 | N4: =AVERAGEIF($A$4:$A$115,N3,$E$4:$E$115) -> 0.050508944
A5: 2014 | B5: February | C5: 41671 | D5: =IF(C5<DATE(2020,3,1),"Pre-Covid","Post-Covid") -> Pre-Covid | E5: =('Question 4 (Data)'!F17-'Question 4 (Data)'!F5)/'Question 4 (Data)'!F5 -> 0.081613508 | F5: =('Question 4 (Data)'!G17-'Question 4 (Data)'!G5)/'Question 4 (Data)'!G5 -> 0.059330144 | G5: =('Question 4 (Data)'!H17-'Question 4 (Data)'!H5)/'Question 4 (Data)'!H5 -> 0.080337756 | H5: =('Question 4 (Data)'!I17-'Question 4 (Data)'!I5)/'Question 4 (Data)'!I5 -> 0.078822412 | K5: Health | L5: =AVERAGEIF($A$4:$A$115,L3,$F$4:$F$115) -> 0.080033677 | M5: =AVERAGEIF($A$4:$A$115,M3,$F$4:$F$115) -> 0.036588631 | N5: =AVERAGEIF($A$4:$A$115,N3,$F$4:$F$115) -> 0.084660073
A6: 2014 | B6: Marcrh | C6: 41699 | D6: =IF(C6<DATE(2020,3,1),"Pre-Covid","Post-Covid") -> Pre-Covid | E6: =('Question 4 (Data)'!F18-'Question 4 (Data)'!F6)/'Question 4 (Data)'!F6 -> 0.08606174 | F6: =('Question 4 (Data)'!G18-'Question 4 (Data)'!G6)/'Question 4 (Data)'!G6 -> 0.060057197 | G6: =('Question 4 (Data)'!H18-'Question 4 (Data)'!H6)/'Question 4 (Data)'!H6 -> 0.080606352 | H6: =('Question 4 (Data)'!I18-'Question 4 (Data)'!I6)/'Question 4 (Data)'!I6 -> 0.082464455 | K6: Essential Servises | L6: =AVERAGEIF($A$4:$A$115,L3,$G$4:$G$115) -> 0.037124175 | M6: =AVERAGEIF($A$4:$A$115,M3,$G$4:$G$115) -> 0.033673286 | N6: =AVERAGEIF($A$4:$A$115,N3,$G$4:$G$115) -> 0.076352205
A7: 2014 | B7: April | C7: 41730 | D7: =IF(C7<DATE(2020,3,1),"Pre-Covid","Post-Covid") -> Pre-Covid | E7: =('Question 4 (Data)'!F19-'Question 4 (Data)'!F7)/'Question 4 (Data)'!F7 -> 0.091922006 | F7: =('Question 4 (Data)'!G19-'Question 4 (Data)'!G7)/'Question 4 (Data)'!G7 -> 0.058879392 | G7: =('Question 4 (Data)'!H19-'Question 4 (Data)'!H7)/'Question 4 (Data)'!H7 -> 0.080633549 | H7: =('Question 4 (Data)'!I19-'Question 4 (Data)'!I7)/'Question 4 (Data)'!I7 -> 0.084825636 | K7: General index | L7: =AVERAGEIF($A$4:$A$115,L3,$H$4:$H$115) -> 0.03972956 | M7: =AVERAGEIF($A$4:$A$115,M3,$H$4:$H$115) -> 0.05021011 | N7: =AVERAGEIF($A$4:$A$115,N3,$H$4:$H$115) -> 0.069717454
A8: 2014 | B8: May | C8: 41760 | D8: =IF(C8<DATE(2020,3,1),"Pre-Covid","Post-Covid") -> Pre-Covid | E8: =('Question 4 (Data)'!F20-'Question 4 (Data)'!F8)/'Question 4 (Data)'!F8 -> 0.088827839 | F8: =('Question 4 (Data)'!G20-'Question 4 (Data)'!G8)/'Question 4 (Data)'!G8 -> 0.055712937 | G8: =('Question 4 (Data)'!H20-'Question 4 (Data)'!H8)/'Question 4 (Data)'!H8 -> 0.080479042 | H8: =('Question 4 (Data)'!I20-'Question 4 (Data)'!I8)/'Question 4 (Data)'!I8 -> 0.083255379
A9: 2014 | B9: June | C9: 41791 | D9: =IF(C9<DATE(2020,3,1),"Pre-Covid","Post-Covid") -> Pre-Covid | E9: =('Question 4 (Data)'!F21-'Question 4 (Data)'!F9)/'Question 4 (Data)'!F9 -> 0.073083779 | F9: =('Question 4 (Data)'!G21-'Question 4 (Data)'!G9)/'Question 4 (Data)'!G9 -> 0.055451128 | G9: =('Question 4 (Data)'!H21-'Question 4 (Data)'!H9)/'Question 4 (Data)'!H9 -> 0.061534862 | H9: =('Question 4 (Data)'!I21-'Question 4 (Data)'!I9)/'Question 4 (Data)'!I9 -> 0.067703568
A10: 2014 | B10: July | C10: 41821 | D10: =IF(C10<DATE(2020,3,1),"Pre-Covid","Post-Covid") -> Pre-Covid | E10: =('Question 4 (Data)'!F22-'Question 4 (Data)'!F10)/'Question 4 (Data)'!F10 -> 0.087183958 | F10: =('Question 4 (Data)'!G22-'Question 4 (Data)'!G10)/'Question 4 (Data)'!G10 -> 0.053271028 | G10: =('Question 4 (Data)'!H22-'Question 4 (Data)'!H10)/'Question 4 (Data)'!H10 -> 0.058877857 | H10: =('Question 4 (Data)'!I22-'Question 4 (Data)'!I10)/'Question 4 (Data)'!I10 -> 0.073873874
A11: 2014 | B11: August | C11: 41852 | D11: =IF(C11<DATE(2020,3,1),"Pre-Covid","Post-Covid") -> Pre-Covid | E11: =('Question 4 (Data)'!F23-'Question 4 (Data)'!F11)/'Question 4 (Data)'!F11 -> 0.085763293 | F11: =('Question 4 (Data)'!G23-'Question 4 (Data)'!G11)/'Question 4 (Data)'!G11 -> 0.053953488 | G11: =('Question 4 (Data)'!H23-'Question 4 (Data)'!H11)/'Question 4 (Data)'!H11 -> 0.054524628 | H11: =('Question 4 (Data)'!I23-'Question 4 (Data)'!I11)/'Question 4 (Data)'!I11 -> 0.070284698 | K11: Year | L11: Food and beverages | M11: Health Care | N11: Essential Sevices | O11: General
A12: 2014 | B12: September | C12: 41883 | D12: =IF(C12<DATE(2020,3,1),"Pre-Covid","Post-Covid") -> Pre-Covid | E12: =('Question 4 (Data)'!F24-'Question 4 (Data)'!F12)/'Question 4 (Data)'!F12 -> 0.06339814 | F12: =('Question 4 (Data)'!G24-'Question 4 (Data)'!G12)/'Question 4 (Data)'!G12 -> 0.051803885 | G12: =('Question 4 (Data)'!H24-'Question 4 (Data)'!H12)/'Question 4 (Data)'!H12 -> 0.046063081 | H12: =('Question 4 (Data)'!I24-'Question 4 (Data)'!I12)/'Question 4 (Data)'!I12 -> 0.056288478 | K12: 2014 | L12: =AVERAGEIF($A$4:$A$115,K12,$E$4:$E$115) -> 0.071834737 | M12: =AVERAGEIF($A$4:$A$115,K12,$F$4:$F$115) -> 0.055088974 | N12: =AVERAGEIF($A$4:$A$115,K12,$G$4:$G$115) -> 0.062781955 | O12: =AVERAGEIF($A$4:$A$115,K12,$H$4:$H$115) -> 0.067099724
A13: 2014 | B13: October | C13: 41913 | D13: =IF(C13<DATE(2020,3,1),"Pre-Covid","Post-Covid") -> Pre-Covid | E13: =('Question 4 (Data)'!F25-'Question 4 (Data)'!F13)/'Question 4 (Data)'!F13 -> 0.043261231 | F13: =('Question 4 (Data)'!G25-'Question 4 (Data)'!G13)/'Question 4 (Data)'!G13 -> 0.052486188 | G13: =('Question 4 (Data)'!H25-'Question 4 (Data)'!H13)/'Question 4 (Data)'!H13 -> 0.045958796 | H13: =('Question 4 (Data)'!I25-'Question 4 (Data)'!I13)/'Question 4 (Data)'!I13 -> 0.046167247 | K13: 2015 | L13: =AVERAGEIF($A$4:$A$115,K13,$E$4:$E$115) -> 0.052842191 | M13: =AVERAGEIF($A$4:$A$115,K13,$F$4:$F$115) -> 0.052502268 | N13: =AVERAGEIF($A$4:$A$115,K13,$G$4:$G$115) -> 0.041187971 | O13: =AVERAGEIF($A$4:$A$115,K13,$H$4:$H$115) -> 0.049128371
A14: 2014 | B14: November | C14: 41944 | D14: =IF(C14<DATE(2020,3,1),"Pre-Covid","Post-Covid") -> Pre-Covid | E14: =('Question 4 (Data)'!F26-'Question 4 (Data)'!F14)/'Question 4 (Data)'!F14 -> 0.020391517 | F14: =('Question 4 (Data)'!G26-'Question 4 (Data)'!G14)/'Question 4 (Data)'!G14 -> 0.05032022 | G14: =('Question 4 (Data)'!H26-'Question 4 (Data)'!H14)/'Question 4 (Data)'!H14 -> 0.042850699 | H14: =('Question 4 (Data)'!I26-'Question 4 (Data)'!I14)/'Question 4 (Data)'!I14 -> 0.032674119 | K14: 2016 | L14: =AVERAGEIF($A$4:$A$115,K14,$E$4:$E$115) -> 0.05373304 | M14: =AVERAGEIF($A$4:$A$115,K14,$F$4:$F$115) -> 0.049114176 | N14: =AVERAGEIF($A$4:$A$115,K14,$G$4:$G$115) -> 0.040593537 | O14: =AVERAGEIF($A$4:$A$115,K14,$H$4:$H$115) -> 0.049603637
